<?xml version="1.0" encoding="utf-8"?>
<!-- This URDF was automatically created by SolidWorks to URDF Exporter! Originally created by Stephen Brawner (brawner@gmail.com) 
     Commit Version: 1.5.1-0-g916b5db  Build Version: 1.5.7152.31018
     For more information, please see http://wiki.ros.org/sw_urdf_exporter -->
<robot name="motar">

<!-- Base_link(Kasa) -->

  <link name="base_link">
    <inertial>
      <origin xyz="0.0038915 -0.00015149 0.11294" rpy="0 0 0" />
      <mass value="5" />
      <inertia
        ixx="0.046794"
        ixy="1.7453E-06"
        ixz="0.00060613"
        iyy="0.082812"
        iyz="1.6068E-06"
        izz="0.1101" />
    </inertial>
    <visual>
      <origin xyz="0 0 0" rpy="0 0 0" />
      <geometry>
        <mesh filename="package://motar/meshes/base_link.dae" />
      </geometry>
      <material name="">
        <color rgba="1 1 1 1" />
      </material>
    </visual>
    <collision>
      <origin xyz="0 0 0" rpy="0 0 0" />
      <geometry>
        <mesh filename="package://motar/meshes/base_link.dae" />
      </geometry>
    </collision>
  </link>

<!-- Dolap -->

  <link
    name="Dolap">
    <inertial>
      <origin xyz="0.03002 -0.00030148 0.2813" rpy="0 0 0" />
      <mass value="10" />
      <inertia
        ixx="0.35346"
        ixy="0.00024128"
        ixz="0.010985"
        iyy="0.23737"
        iyz="0.00029637"
        izz="0.25603" />
    </inertial>
    <visual>
      <origin xyz="0 0 0" rpy="0 0 0" />
      <geometry>
        <mesh filename="package://motar/meshes/Dolap.dae" />
      </geometry>
      <material name="">
        <color rgba="0.29804 0.29804 0.29804 1" />
      </material>
    </visual>
    <collision>
      <origin xyz="0 0 0" rpy="0 0 0" />
      <geometry>
        <mesh filename="package://motar/meshes/Dolap.dae" />
      </geometry>
    </collision>
  </link>
  <joint name="dolap" type="fixed">
    <origin xyz="0 0 0.171" rpy="0 0 -1.5707963267949" />
    <parent link="base_link" />
    <child link="Dolap" />
    <axis xyz="0 0 0" />
  </joint>

<!-- Kapak -->

  <link name="Kapak">
    <inertial>
      <origin xyz="-0.0014014 -2.2204E-16 -0.0050004" rpy="0 0 0" />
      <mass value="2" />
      <inertia
        ixx="0.021226"
        ixy="1.4846E-17"
        ixz="1.1211E-07"
        iyy="0.020927"
        iyz="-4.3721E-19"
        izz="0.042127" />
    </inertial>
    <visual>
      <origin xyz="0 0 0" rpy="0 0 0" />
      <geometry>
        <mesh filename="package://motar/meshes/Kapak.dae" />
      </geometry>
      <material name="">
        <color rgba="0.79216 0.81961 0.93333 1" />
      </material>
    </visual>
    <collision>
      <origin xyz="0 0 0" rpy="0 0 0" />
      <geometry>
        <mesh filename="package://motar/meshes/Kapak.dae" />
      </geometry>
    </collision>
  </link>
  <joint name="kapak" type="fixed">
    <origin xyz="0.00191317694878623 0.151913176948787 0.371" rpy="-1.5707963267949 0 3.14159265358979" />
    <parent link="base_link" />
    <child link="Kapak" />
    <axis xyz="0 0 0" />
  </joint>

<!-- Menteşe 1 -->

  <link
    name="Mentese1">
    <inertial>
      <origin xyz="0.040745 -0.00074504 0.062421" rpy="0 0 0" />
      <mass value="0.02" />
      <inertia
        ixx="2.5219E-06"
        ixy="6.5868E-09"
        ixz="-4.2442E-08"
        iyy="5.0301E-07"
        iyz="6.5777E-09"
        izz="2.5221E-06" />
    </inertial>
    <visual>
      <origin xyz="0 0 0" rpy="0 0 0" />
      <geometry>
        <mesh filename="package://motar/meshes/Mentese1.dae" />
      </geometry>
      <material name="">
        <color rgba="0.75294 0.75294 0.75294 1" />
      </material>
    </visual>
    <collision>
      <origin xyz="0 0 0" rpy="0 0 0" />
      <geometry>
        <mesh filename="package://motar/meshes/Mentese1.dae" />
      </geometry>
    </collision>
  </link>
  <joint name="mentese1" type="fixed">
    <origin
      xyz="-0.131975069002989 0.187039265224648 0.471745038931026"
      rpy="1.5707963267949 0 -1.57149034875903" />
    <parent link="base_link" />
    <child link="Mentese1" />
    <axis xyz="0 0 0" />
  </joint>

<!-- Menteşe 2 -->

  <link
    name="Mentese2">
    <inertial>
      <origin
        xyz="0.040745 -0.00074504 0.062421"
        rpy="0 0 0" />
      <mass
        value="0.02" />
      <inertia
        ixx="2.5219E-06"
        ixy="6.5868E-09"
        ixz="-4.2442E-08"
        iyy="5.0301E-07"
        iyz="6.5777E-09"
        izz="2.5221E-06" />
    </inertial>
    <visual>
      <origin
        xyz="0 0 0"
        rpy="0 0 0" />
      <geometry>
        <mesh
          filename="package://motar/meshes/Mentese2.dae" />
      </geometry>
      <material
        name="">
        <color
          rgba="0.75294 0.75294 0.75294 1" />
      </material>
    </visual>
    <collision>
      <origin
        xyz="0 0 0"
        rpy="0 0 0" />
      <geometry>
        <mesh
          filename="package://motar/meshes/Mentese2.dae" />
      </geometry>
    </collision>
  </link>
  <joint
    name="mentese2"
    type="fixed">
    <origin
      xyz="0 -0.2 0"
      rpy="0 0 0" />
    <parent
      link="Mentese1" />
    <child
      link="Mentese2" />
    <axis
      xyz="0 0 0" />
  </joint>

<!-- Wheel1 -->

  <link
    name="Wheel1">
    <inertial>
      <origin
        xyz="0.013121 -1.1102E-16 2.7756E-17"
        rpy="0 0 0" />
      <mass
        value="0.2" />
      <inertia
        ixx="0.00032266"
        ixy="2.9778E-20"
        ixz="1.0838E-20"
        iyy="0.00016712"
        iyz="-5.0764E-17"
        izz="0.00016712" />
    </inertial>
    <visual>
      <origin
        xyz="0 0 0"
        rpy="0 0 0" />
      <geometry>
        <mesh
          filename="package://motar/meshes/Wheel1.dae" />
      </geometry>
      <material
        name="">
        <color
          rgba="0.75294 0.75294 0.75294 1" />
      </material>
    </visual>
    <collision>
      <origin
        xyz="0 0 0"
        rpy="0 0 0" />
      <geometry>
        <mesh
          filename="package://motar/meshes/Wheel1.dae" />
      </geometry>
    </collision>
  </link>
  <joint
    name="wheel1"
    type="continuous">
    <origin
      xyz="-0.07 0.125 0.06"
      rpy="-1.5708 0 1.5708" />
    <parent
      link="base_link" />
    <child
      link="Wheel1" />
    <axis
      xyz="1 0 0" />
  </joint>

<!-- Ultrasonic Sensor1 -->

  <link
    name="US1">
    <inertial>
      <origin
        xyz="-0.049168 -0.077613 0.0040046"
        rpy="0 0 0" />
      <mass
        value="0.1" />
      <inertia
        ixx="1.74E-07"
        ixy="1.6556E-09"
        ixz="-3.9566E-10"
        iyy="8.8636E-07"
        iyz="-2.8114E-09"
        izz="9.3681E-07" />
    </inertial>
    <visual>
      <origin
        xyz="0 0 0"
        rpy="0 0 0" />
      <geometry>
        <mesh
          filename="package://motar/meshes/US1.dae" />
      </geometry>
      <material
        name="">
        <color
          rgba="0.79216 0.81961 0.93333 1" />
      </material>
    </visual>
    <collision>
      <origin
        xyz="0 0 0"
        rpy="0 0 0" />
      <geometry>
        <mesh
          filename="package://motar/meshes/US1.dae" />
      </geometry>
    </collision>
  </link>
  <joint
    name="us1"
    type="fixed">
    <origin
      xyz="0.1985 -0.037521 0.17766"
      rpy="1.5708 0 1.5708" />
    <parent
      link="base_link" />
    <child
      link="US1" />
    <axis
      xyz="0 0 0" />
  </joint>

<!-- Ultrasonic Sensor2 -->

  <link
    name="US2">
    <inertial>
      <origin
        xyz="-0.049168 -0.077613 0.0040046"
        rpy="0 0 0" />
      <mass
        value="0.1" />
      <inertia
        ixx="1.74E-07"
        ixy="1.6556E-09"
        ixz="-3.9566E-10"
        iyy="8.8636E-07"
        iyz="-2.8114E-09"
        izz="9.3681E-07" />
    </inertial>
    <visual>
      <origin
        xyz="0 0 0"
        rpy="0 0 0" />
      <geometry>
        <mesh
          filename="package://motar/meshes/US2.dae" />
      </geometry>
      <material
        name="">
        <color
          rgba="0.79216 0.81961 0.93333 1" />
      </material>
    </visual>
    <collision>
      <origin
        xyz="0 0 0"
        rpy="0 0 0" />
      <geometry>
        <mesh
          filename="package://motar/meshes/US2.dae" />
      </geometry>
    </collision>
  </link>
  <joint
    name="us2"
    type="fixed">
    <origin
      xyz="0.1985 0.049149 0.17766"
      rpy="1.5708 0 1.5708" />
    <parent
      link="base_link" />
    <child
      link="US2" />
    <axis
      xyz="0 0 0" />
  </joint>

<!-- Ultrasonic Sensor3 -->

  <link
    name="US3">
    <inertial>
      <origin
        xyz="-0.049168 -0.077613 0.0040046"
        rpy="0 0 0" />
      <mass
        value="0.1" />
      <inertia
        ixx="1.74E-07"
        ixy="1.6556E-09"
        ixz="-3.9566E-10"
        iyy="8.8636E-07"
        iyz="-2.8114E-09"
        izz="9.3681E-07" />
    </inertial>
    <visual>
      <origin
        xyz="0 0 0"
        rpy="0 0 0" />
      <geometry>
        <mesh
          filename="package://motar/meshes/US3.dae" />
      </geometry>
      <material
        name="">
        <color
          rgba="0.79216 0.81961 0.93333 1" />
      </material>
    </visual>
    <collision>
      <origin
        xyz="0 0 0"
        rpy="0 0 0" />
      <geometry>
        <mesh
          filename="package://motar/meshes/US3.dae" />
      </geometry>
    </collision>
  </link>
  <joint
    name="us3"
    type="fixed">
    <origin
      xyz="0.1985 0.13582 0.17766"
      rpy="1.5708 0 1.5708" />
    <parent
      link="base_link" />
    <child
      link="US3" />
    <axis
      xyz="0 0 0" />
  </joint>
  
<!-- Swivel Wheel1 -->

  <link name="SWheel1">
    <inertial>
      <origin xyz="4.839E-08 0.0155 0.022137" rpy="0 0 0" />
      <mass value="0.2" />
      <inertia
        ixx="1.3179E-07"
        ixy="-2.0283E-12"
        ixz="5.5707E-13"
        iyy="1.4756E-07"
        iyz="-1.059E-12"
        izz="2.6348E-07" />
    </inertial>
    <visual>
      <origin
        xyz="0 0 0"
        rpy="0 0 0" />
      <geometry>
        <mesh filename="package://motar/meshes/SWheel1.dae" />
      </geometry>
      <material name="">
        <color rgba="0.79216 0.81961 0.93333 1" />
      </material>
    </visual>
    <collision>
      <origin xyz="0 0 0" rpy="0 0 0" />
      <geometry>
        <mesh filename="package://motar/meshes/SWheel1.dae" />
      </geometry>
    </collision>
  </link>
  <joint name="splate1" type="fixed">
    <origin xyz="0.1685 0.12117 0.015" rpy="0 0 -1.5708" />
    <parent link="base_link" />
    <child link="SWheel1" />
    <axis xyz="0 0 0" />
  </joint>
  <link name="SWhSup1">
    <inertial>
      <origin xyz="-0.00046958 -0.0066637 0.011394" rpy="0 0 0" />
      <mass value="0.3" />
      <inertia
        ixx="2.9995E-07"
        ixy="-9.3755E-09"
        ixz="-1.2195E-08"
        iyy="2.9321E-07"
        iyz="-9.2072E-08"
        izz="3.2439E-07" />
    </inertial>
    <visual>
      <origin xyz="0 0 0" rpy="0 0 0" />
      <geometry>
        <mesh filename="package://motar/meshes/SWhSup1.dae" />
      </geometry>
      <material name="">
        <color rgba="0.79216 0.81961 0.93333 1" />
      </material>
    </visual>
    <collision>
      <origin
        xyz="0 0 0"
        rpy="0 0 0" />
      <geometry>
        <mesh filename="package://motar/meshes/SWhSup1.dae" />
      </geometry>
    </collision>
  </link>
  <joint name="swhsup1" type="continuous">
    <origin xyz="0 0.0154999999999999 0" rpy="0 0 0" />
    <parent link="SWheel1" />
    <child link="SWhSup1" />
    <axis xyz="0 0 1" />
  </joint>
  <link name="SWh1">
    <inertial>
      <origin xyz="-1.8715E-07 0 1.4278E-06" rpy="0 0 0" />
      <mass value="0.5" />
      <inertia
        ixx="7.3808E-07"
        ixy="-4.8488E-13"
        ixz="1.2219E-11"
        iyy="4.3737E-07"
        iyz="9.1434E-22"
        izz="4.3728E-07" />
    </inertial>
    <visual>
      <origin xyz="0 0 0" rpy="0 0 0" />
      <geometry>
        <mesh filename="package://motar/meshes/SWh1.dae" />
      </geometry>
      <material name="">
        <color rgba="0.79216 0.81961 0.93333 1" />
      </material>
    </visual>
    <collision>
      <origin xyz="0 0 0" rpy="0 0 0" />
      <geometry>
        <mesh filename="package://motar/meshes/SWh1.dae" />
      </geometry>
    </collision>
  </link>
  <joint name="swheel1" type="continuous">
    <origin xyz="0 -0.0154999999999991 -9.9999999999878E-05" rpy="0 0 0" />
    <parent link="SWhSup1" />
    <child link="SWh1" />
    <axis xyz="1 0 0" />
  </joint>

<!-- Swivel Wheel2 -->

  <link name="SWheel2">
    <inertial>
      <origin xyz="4.839E-08 0.0155 0.022137" rpy="0 0 0" />
      <mass value="0.2" />
      <inertia ixx="1.3179E-07" ixy="-2.0283E-12" ixz="5.5707E-13" iyy="1.4756E-07" iyz="-1.059E-12" izz="2.6348E-07" />
    </inertial>
    <visual>
      <origin xyz="0 0 0" rpy="0 0 0" />
      <geometry>
        <mesh filename="package://motar/meshes/SWheel2.dae" />
      </geometry>
      <material name="">
        <color rgba="0.79216 0.81961 0.93333 1" />
      </material>
    </visual>
    <collision>
      <origin xyz="0 0 0" rpy="0 0 0" />
      <geometry>
        <mesh filename="package://motar/meshes/SWheel2.dae" />
      </geometry>
    </collision>
  </link>
  <joint name="splate2" type="fixed">
    <origin xyz="0.1685 -0.121 0.015" rpy="0 0 -1.5708" />
    <parent link="base_link" />
    <child link="SWheel2" />
    <axis xyz="0 0 0" />
  </joint>
  <link name="SWhSup2">
    <inertial>
      <origin xyz="-0.00046958 -0.0066637 0.011394" rpy="0 0 0" />
      <mass value="0.3" />
      <inertia ixx="2.9995E-07" ixy="-9.3755E-09" ixz="-1.2195E-08" iyy="2.9321E-07" iyz="-9.2072E-08" izz="3.2439E-07" />
    </inertial>
    <visual>
      <origin xyz="0 0 0" rpy="0 0 0" />
      <geometry>
        <mesh filename="package://motar/meshes/SWhSup2.dae" />
      </geometry>
      <material name="">
        <color rgba="0.79216 0.81961 0.93333 1" />
      </material>
    </visual>
    <collision>
      <origin xyz="0 0 0" rpy="0 0 0" />
      <geometry>
        <mesh filename="package://motar/meshes/SWhSup2.dae" />
      </geometry>
    </collision>
  </link>
  <joint name="swhsup2" type="continuous">
    <origin xyz="0 0.0154999999999999 0" rpy="0 0 0" />
    <parent link="SWheel2" />
    <child link="SWhSup2" />
    <axis xyz="0 0 1" />
  </joint>
  <link name="SWh2">
    <inertial>
      <origin xyz="-1.8715E-07 -1.3878E-17 1.4278E-06" rpy="0 0 0" />
      <mass value="0.5" />
      <inertia ixx="7.3808E-07" ixy="-4.8488E-13" ixz="1.2219E-11" iyy="4.3737E-07" iyz="4.125E-22" izz="4.3728E-07" />
    </inertial>
    <visual>
      <origin xyz="0 0 0" rpy="0 0 0" />
      <geometry>
        <mesh filename="package://motar/meshes/SWh2.dae" />
      </geometry>
      <material name="">
        <color rgba="0.79216 0.81961 0.93333 1" />
      </material>
    </visual>
    <collision>
      <origin xyz="0 0 0" rpy="0 0 0" />
      <geometry>
        <mesh filename="package://motar/meshes/SWh2.dae" />
      </geometry>
    </collision>
  </link>
  <joint name="swheel2" type="continuous">
    <origin xyz="0 -0.0155 -9.99999999983237E-05" rpy="0 0 0" />
    <parent link="SWhSup2" />
    <child link="SWh2" />
    <axis xyz="1 0 0" />

<!-- Wheel2 -->

  </joint>
  <link name="Wheel2">
    <inertial>
      <origin xyz="0.013121 1.1102E-16 2.7756E-17" rpy="0 0 0" />
      <mass value="0.2" />
      <inertia ixx="0.00032266" ixy="-5.455E-21" ixz="-2.0078E-20" iyy="0.00016712" iyz="7.6555E-18" izz="0.00016712" />
    </inertial>
    <visual>
      <origin xyz="0 0 0" rpy="0 0 0" />
      <geometry>
        <mesh filename="package://motar/meshes/Wheel2.dae" />
      </geometry>
      <material name="">
        <color rgba="0.75294 0.75294 0.75294 1" />
      </material>
    </visual>
    <collision>
      <origin xyz="0 0 0" rpy="0 0 0" />
      <geometry>
        <mesh filename="package://motar/meshes/Wheel2.dae" />
      </geometry>
    </collision>
  </link>
  <joint name="wheel2" type="continuous">
    <origin xyz="-0.07 -0.125 0.06" rpy="-1.5708 0 -1.5708" />
    <parent link="base_link" />
    <child link="Wheel2" />
    <axis xyz="-1 0 0" />
  </joint>

<!-- Lidar Sensor -->

<link name="Lidar">
    <inertial>
      <origin xyz="9.1926E-05 -0.0074835 0.010668" rpy="0 0 0" />
      <mass value="0.5" />
      <inertia ixx="0.0009607" ixy="8.0198E-07" ixz="3.0916E-06" iyy="0.00061492" iyz="0.00015824" izz="0.0010982" />
    </inertial>
    <visual>
      <origin xyz="0 0 0" rpy="0 0 0" />
      <geometry>
        <mesh filename="package://motar/meshes/Lidar.dae" />
      </geometry>
      <material name="">
        <color rgba="0.79216 0.81961 0.93333 1" />
      </material>
    </visual>
    <collision>
      <origin xyz="0 0 0" rpy="0 0 0" />
      <geometry>
        <mesh filename="package://motar/meshes/Lidar.dae" />
      </geometry>
    </collision>
  </link>
  <joint name="lidar" type="fixed">
    <origin xyz="0 0.0094475 0.8256" rpy="0 0 0" />
    <parent link="base_link" />
    <child link="Lidar" />
    <axis xyz="0 0 0" />
  </joint>

<!-- hokuyo Sensor Plugin-->

 	<gazebo reference="Lidar">
		<sensor type="gpu_ray" name="head_hokuyo_sensor">
		<pose>0 0 0 1 0 0</pose>
		<visualize>true</visualize>
		<update_rate>40</update_rate>
		<ray>
		<scan>
			<horizontal>
				<samples>720</samples>
				<resolution>1</resolution>
				<min_angle>-3.1416</min_angle>
				<max_angle>3.1416</max_angle>
			</horizontal>
		</scan>
		<range>
			<min>1.5</min>
			<max>5.0</max>
			<resolution>0.1</resolution>
		</range>
		<noise>
			<type>gaussian</type>
			<mean>0.0</mean>
			<stddev>0.01</stddev>
		</noise>
		</ray>

		<plugin name="gazebo_ros_head_hokuyo_controller" filename="libgazebo_ros_gpu_laser.so">
			<topicName>laser</topicName>
			<frameName>laser</frameName>
			</plugin>
			</sensor>
	</gazebo>

<!-- Diff Drive Control Plugin -->

  <gazebo>
     <plugin name="differential_drive_controller" filename="libgazebo_ros_diff_drive.so">
       <alwaysOn>true</alwaysOn>
       <legacyMode>false</legacyMode>
       <updateRate>40</updateRate>
       <leftJoint>wheel1</leftJoint>
       <rightJoint>wheel2</rightJoint>
       <wheelSeparation>0.42</wheelSeparation>
       <wheelDiameter>0.12</wheelDiameter>
       <torque>20</torque>
       <commandTopic>cmd_vel</commandTopic>
       <odometryTopic>odom</odometryTopic>
       <odometryFrame>odom</odometryFrame>
       <robotBaseFrame>base_link</robotBaseFrame>
       <robotNamespace>/</robotNamespace>
     </plugin>
  </gazebo> 

</robot>
